Workbook

Sheet BOM
A1: Counter-UAS Turret - Bill of Materials (one row per part)
A2: Updated 2026-10-16. Status: Verified = I opened the live page and saw this price/stock. Needs check = price seen in a search result or unconfirmed detail. Estimate = my guess, no listing. Blue = typed-in input. Qty 0 = not counted in totals. Shipping and tax NOT included.
A4: # | B4: Subsystem | C4: Part name | D4: Specific component | E4: Qty | F4: Prototype | G4: Status | H4: Unit price ($) | I4: Ext. price ($) | J4: Vendor | K4: Link | L4: Est. arrival | M4: Why I chose it | N4: CAD footprint | O4: KiCad footprint | P4: Notes / watch-outs | Q4: Decide by | R4: Order by
A5: PROTOTYPE 1 - order now (breadboard motors + trained model + laser)
A6: 1 | B6: Control | C6: Microcontroller dev board | D6: STMicroelectronics NUCLEO-G474RE (Nucleo-64, STM32G474RE) | E6: 1 | F6: P1 | G6: Verified | H6: 20.13 | I6: =IF(H6="","",E6*H6) -> 20.13 | J6: Digi-Key | K6: Link | L6: Digi-Key. Shipping time not shown on the page; confirm at checkout. | M6: I wanted the motor brain to be the one the industry or resume people will like better, so STM32 instead of ESP32, with one condition: it must cost only about 5 extra hours, because time is my tightest limit (10-12 hrs/week). We used Arduino-style code (PlatformIO) to hold it to that. The Nucleo-G474RE is a chip plus a built-in USB programmer on one board, so I can start testing motors right away. The G474 was chosen because the G431RB is out of stock with a 99-week lead time. Escape hatch: if no motor is turning by Oct 26, I switch to an ESP32-S3. I also chose to make my custom PCB a carrier board that this Nucleo plugs into, so this board stays in the finished turret. | P6: Seen in stock (1,981) on digikey.com. Its '99 weeks' is the restock lead time, not your wait. Amazon sellers charge $88-349, do not buy there. Ask the Purdue ECE shop first; if they have a Nucleo board, skip this. | Q6: Oct 19 (after ECE shop check) | R6: Mon Oct 19 (Digi-Key) if ECE has none
A7: 2 | B7: Motion | C7: Closed-loop motor + driver kit (pan + tilt) | D7: BIGTREETECH S42C V1.1 + metal cover + motor kit (Octobigtree) | E7: 2 | F7: P1 | G7: Verified | H7: 39.99 | I7: =IF(H7="","",E7*H7) -> 79.98 | J7: Amazon | K7: Link | L7: Listing showed delivery Sun Oct 18 on your screen. | M7: Closed-loop motors were in the original spec: backlash and lost steps were named as a top failure risk, and a turret has to turn fast to track a moving target without losing its aim. I need motors soon so I can start the CAD, the breadboard wiring and model training, so the pick had to arrive in days. The BTT S42C kit includes the motor, the driver and the position sensor, so there is nothing to match up, costs $39.99 each, and Amazon showed delivery Oct 18. Plain steppers with separate drivers (about $50 for two axes) were rejected as open-loop. I chose 12 V for the motor rail because a 12 V battery is much cheaper than a 24 V one, and my rule was: if it is not that much slower, go 12 V. The 24 V hedge came from my worry that a turret must move fast: the PCB parts are rated for 24 V so I can upgrade later without a new board. | P7: Motor is included per the listing title ('S42C V1.1 + Metal Protective Cover + Motor'). Voltage is not stated on the page; BTT's V1.0 manual rates 1.65 A at 12 V. Power it first from the bench supply at 12 V with about a 1 A current limit. Pinout in the V1.0 manual may differ from V1.1, so read the labels printed on your board. 30-day free returns if a unit is dead (some reviewers report dead units). | Q7: Decided | R7: Mon Oct 19 (Amazon)
A8: 3 | B8: Laser | C8: Laser module (lock-on indicator) | D8: AREALER 4-pack 5 mW 650 nm red dot laser modules, 5 V (Walmart item 14322024651) | E8: 1 | F8: P1 | G8: Verified | H8: 7.61 | I8: =IF(H8="","",E8*H8) -> 7.61 | J8: Walmart | K8: Link | L8: Free shipping; arrival date needs your ZIP code (not checked). | M8: I want the laser in Prototype 1 because I want to see the result of it firing when the model detects. I chose this cheap 4-pack ($7.61) over the $25 Quarton to save about $17 and said not to worry about the maker's power guarantee. 4 modules also means spares while I test the wiring. | P8: 5 mW = Class 3R, ABOVE the project's 1 mW rule, and unbranded with no ratings, so the real power is unknown. Wall or paper target only, never aim at people, pets or shiny surfaces, never look into it. Do not call it Class 2. | Q8: Decided | R8: Mon Oct 19; check arrival ZIP
A9: 4 | B9: Laser | C9: Laser switch (transistor) | D9: Infineon IRLZ44NPBF logic-level MOSFET, single (Digi-Key 811808) | E9: 2 | F9: P1 | G9: Verified | H9: 1.8 | I9: =IF(H9="","",E9*H9) -> 3.6 | J9: Digi-Key | K9: Link | L9: Digi-Key. Shipping time not shown on the page; confirm at checkout. | M9: An STM32 pin is too weak to power the laser by itself, so this small electronic switch lets the pin turn the laser on and off while the power comes from 5 V. I approved swapping the $8.99 Amazon 5-pack for 2 single parts at Digi-Key for $1.80 each, which saves about $5 and goes in the Digi-Key order I am already placing. Quantity 2 gives one spare. | P9: Qty 2 = one spare. $1.80 each, 45,069 in stock (checked Oct 17). Replaced the $8.99 Amazon 5-pack. Probably free from the ECE shop (any small logic-level MOSFET works). | Q9: Decided | R9: Mon Oct 19 (Digi-Key)
A10: 5 | B10: Vision | C10: USB camera (final camera) | D10: Arducam 1080p HDR autofocus USB camera module, 78 deg diagonal, metal body (ASIN B0FX47YSJQ) | E10: 1 | F10: P1 | G10: Verified | H10: 19.99 | I10: =IF(H10="","",E10*H10) -> 19.99 | J10: Amazon | K10: Link | L10: Page showed free delivery Mon Oct 19 (order within ~8 hours of Oct 17 evening). | M10: My two reasons: (1) I want the model trained on the same camera the turret will actually use, because a different camera changes the picture quality and hurts training; (2) the camera mount in my CAD depends on the camera's exact size, so choosing the final camera now means I do not redo the CAD. I do NOT want to buy the Pi now, and the Pi camera only works on a Pi, so I needed a camera that plugs into both my laptop and the Pi later: a USB camera. I set a $27 ceiling and picked this Arducam for autofocus, a narrower 78-degree view, a 1 m cable in the box and a small metal body I can unscrew from its stand and mount in a printed holder. I accepted a cheaper picture than the $39-65 cameras and may upgrade once I am committed. | P10: You plan to unscrew it from its stand and mount just the case. When it arrives, check MJPG 1920x1080 at 30 fps is listed (v4l2-ctl --list-formats-ext on Linux, or OBS on your laptop); return it if not. Includes a 1 m USB cable with a JST connector. Only 22 ratings, 4.0 stars (100+ bought last month). The page does not list MJPEG, cable length, size or weight: get the dimensions before finishing the camera mount in CAD. Cheaper picture quality than the $39-65 cameras. Fallbacks: Arducam IMX219 autofocus $38.99 (B09BR1RNSN), ELP IMX362 $64.99 (B0DQNP1MP9). | Q10: Decided | R10: Today/Sat night for Mon Oct 19 delivery (Amazon)
A11: 6 | B11: Power | C11: 12 V wall adapter | D11: Facmogu 12 V 5 A, 60 W AC-DC adapter (ASIN B0711Q5B49) | E11: 1 | F11: P1 | G11: Needs check | H11: 11.99 | I11: =IF(H11="","",E11*H11) -> 11.99 | J11: Amazon | K11: Link | L11: Not seen. Check the listing. | M11: I asked whether the turret could run from a simple laptop charger for now and do the battery later, because the battery set was expensive and I cannot spend $300 in one month. A 12 V 5 A wall adapter is the cheap answer: 12 V is the motor voltage I picked, and 5 A (60 W) covers the estimated peak of about 87 W with some margin. The ECE shop may have one for free, so I will check Monday before buying. | P11: Check the plug is 5.5x2.1 mm (the title does not say). The ECE shop may have a 12 V supply you can use. | Q11: Oct 19 (after ECE shop check) | R11: Mon Oct 19 (Amazon)
A12: 7 | B12: Power | C12: Barrel jack to screw terminals | D12: 20-pack female DC barrel jack (5.5x2.1 mm) to screw terminal adapters (ASIN B0C4JJ2HB4) | E12: 1 | F12: P1 | G12: Needs check | H12: 6.99 | I12: =IF(H12="","",E12*H12) -> 6.99 | J12: Amazon | K12: Link | L12: Not seen. Check the listing. | M12: Lets me plug the wall adapter in and get two plain wires (+ and -) for the breadboard without cutting the adapter's cable. I wanted every part as its own row with its own link, with nothing bundled. The ECE shop may have a jack. | P12: Pack of 20, you need one. The ECE shop may have a barrel jack. | Q12: Oct 19 (after ECE shop check) | R12: Mon Oct 19 (Amazon)
A13: 8 | B13: Power | C13: Fuse holder | D13: Inline ATC (regular size) blade fuse holder, rated 15 A or more. Reference part: Bussmann #12, Hemlock SKU 580112 | E13: 1 | F13: P1 | G13: Estimate | H13: 5 | I13: =IF(H13="","",E13*H13) -> 5 | J13: Auto parts store / ECE shop (Hemlock = fallback) | K13: Link | L13: Same day at a local store (not checked). Hemlock fallback: in stock, 1-2 day delivery. | M13: I asked what a fuse is and why I need it: it is a cheap part that melts on a short circuit and cuts power before wires get hot, and the holder lets me replace it. I chose to skip the online store (Hemlock) because of its shipping cost and to buy at an auto parts store or get it from the ECE shop. Must be a regular ATC size, rated 15 A or more. | P13: Skip Hemlock (shipping). Buy at AutoZone/O'Reilly or ask the ECE shop. Must be regular ATC size (not Mini/Micro), 15 A or more, with thick wire. Price is a guess. | Q13: Oct 19 (after ECE shop check) | R13: Mon Oct 19 (local store)
A14: 9 | B14: Power | C14: Fuse | D14: 15 A regular-size ATC blade fuses, multi-pack. Reference part: Bussmann 4-pack, Hemlock SKU 573597 | E14: 1 | F14: P1 | G14: Estimate | H14: 6 | I14: =IF(H14="","",E14*H14) -> 6 | J14: Auto parts store / ECE shop (Hemlock = fallback) | K14: Link | L14: Same day at a local store (not checked). Hemlock fallback: in stock, 1-2 day delivery. | M14: Same reasoning as the holder: protects the wiring in a short. 15 A is above the estimated 10 A peak so it will not blow during normal motor bursts. I will buy local or from the ECE shop to avoid shipping. | P14: Buy spares. If it blows, find out why before replacing it. | Q14: Oct 19 (after ECE shop check) | R14: Mon Oct 19 (local store)
A15: 10 | B15: Power | C15: Spike protector (TVS diode) | D15: Littelfuse SMCJ15A, 15 V standoff, DO-214AB | E15: 1 | F15: P1 | G15: Needs check | H15: 0.99 | I15: =IF(H15="","",E15*H15) -> 0.99 | J15: Digi-Key | K15: Link | L15: Digi-Key. Shipping time not shown on the page; confirm at checkout. | M15: Motors switching on and off create brief voltage spikes far above 12 V, and this part clamps them so they cannot hurt the drivers or the chip. It fits my 24 V upgrade hedge (I swap it for a higher-voltage version if I move to 24 V). It costs $0.99. | P15: Use digikey.com, not the Australian site. Price/stock came from Grok, not confirmed by me (I confirmed the part and its 24.4 V clamp). If you move to 24 V later, swap this for a higher-voltage version. | Q15: Decided | R15: Mon Oct 19 (Digi-Key)
A16: 11 | B16: Power | C16: Bulk capacitor | D16: 1000 uF, 35 V electrolytic. Fallback: Lumenier XT60 pigtail + 35 V 1000 uF capacitor, 12 AWG, 3-pack (GetFPV) | E16: 0 | F16: P1 | G16: Verified | H16: 10.99 | I16: =IF(H16="","",E16*H16) -> 0 | J16: GetFPV (fallback) | K16: Link | L16: Site said in stock, same-day shipping (checked earlier). | M16: A small water tank for electricity that smooths the motors' power gulps. I can probably get general parts like this free from the Purdue ECE shop, so it is qty 0 unless they have none. | P16: Qty 0 because the ECE shop likely has a 1000 uF / 35 V capacitor for free. Only buy this pack if they do not. | Q16: Oct 19 (ECE shop) | R16: Only if ECE has none: by Oct 22
A17: 12 | B17: Wiring | C17: Breadboard, jumper wires, USB cable | D17: Already owned | E17: 0 | F17: P1 | G17: Owned | H17: 0 | I17: =IF(H17="","",E17*H17) -> 0 | J17: n/a | L17: n/a | M17: I already have wires and probably a USB cable, so these are not bought. | P17: Need a USB cable that matches the Nucleo's port. Check what it uses.
A18: 13 | B18: Wiring | C18: USB data cable for the Nucleo (only if needed) | D18: USB data cable matching the Nucleo's programming connector (Type-C, Micro-B or Mini-B) | E18: 0 | F18: P1 | G18: Owned | I18: =IF(H18="","",E18*H18) | J18: Own / ECE shop / Amazon | L18: n/a | M18: I have a Type-C cable for sure and will buy a Micro-B or Mini-B data cable only if the Nucleo needs one (about $5). | P18: ST's page says the programming connector can be Type-C, Micro-B or Mini-B depending on the board. Check the board photo or the ECE shop board. It must be a data cable, not charge-only. | Q18: Oct 19 (check the Nucleo connector) | R18: Only if needed
A19: 14 | B19: Mechanical | C19: Screws, standoffs, fasteners | D19: M3 screw assortment (motor mounts are M3 on NEMA 17) plus whatever your CAD needs | E19: 1 | F19: P1 | G19: Estimate | H19: 15 | I19: =IF(H19="","",E19*H19) -> 15 | J19: Amazon / hardware store | L19: n/a | M19: I have access to a 3D printer, so I print the pan-tilt frame and the camera holder, and I can only list exact screw sizes after the CAD is done. I do not own screws but can get them. This $15 is a placeholder. | P19: Allowance only. Finish the CAD, then list exact screw sizes and lengths before buying. You can print the structure yourself. | Q19: After CAD is done (~Oct 24) | R19: ~Oct 24-26, before first build
A20: 15 | B20: Test | C20: Multimeter | D20: Borrowed from a lab or a friend | E20: 0 | F20: P1 | G20: Borrowed | H20: 0 | I20: =IF(H20="","",E20*H20) -> 0 | J20: n/a | L20: n/a | M20: To measure voltage and find shorts before connecting anything expensive. Borrowed. | P20: Bench supply: use a ~1 A current limit for first power-up.
C21: PROTOTYPE 1 TOTAL | I21: =SUMIFS($I$5:$I$20,$F$5:$F$20,"P1") -> 177.28
A22: PCB - order by Nov 2 (ships during exam dead zone). Parts depend on your design. Prices are estimates.
A23: 16 | B23: PCB | C23: DECISION (pinned): power input connector on PCB | D23: Suggested: screw terminal (takes a wall adapter now, a battery later) | E23: 0 | F23: PCB | G23: Open | I23: =IF(H23="","",E23*H23) | J23: n/a | L23: n/a | M23: I chose option D on Oct 17: a barrel jack AND an XT60 battery connector footprint, only one connected at a time. The wall adapter plugs into the barrel jack today and cannot go in backwards; a battery drops into the XT60 later with no redesign. A bare screw terminal was rejected because it can be wired backwards and loosen from vibration. The PCB is only ordered once, so the way power enters has to be right the first time. | P23: Pinned. Discuss after the other open items. Not a purchase. | Q23: Oct 30 (PCB design) | R23: n/a
A24: 17 | B24: PCB | C24: PCB fabrication | D24: 5 boards, 2 layers, from JLCPCB or PCBWay (your design) | E24: 1 | F24: PCB | G24: Estimate | H24: 25 | I24: =IF(H24="","",E24*H24) -> 25 | J24: JLCPCB / PCBWay | L24: Order by Nov 2. | M24: I will not compromise on the custom PCB: it is the hardware half of my resume line. The board is a carrier board that the Nucleo plugs into, which I chose over a bare-chip board to cut risk (no fine-pitch chip soldering, no chip start-up problems) while keeping a real PCB design with real soldering. It must be ordered by Nov 2 so it ships during the exam dead zone. | P24: Estimate includes shipping. Get a quote when the design is done. | Q24: Design done Oct 30 | R24: By Nov 2
A25: 18 | B25: PCB | C25: Microcontroller chip (OPTIONAL, not counted) | D25: STM32G474 (package chosen in your design), same family as the Nucleo | E25: 0 | F25: PCB | G25: Needs check | H25: 10.7 | I25: =IF(H25="","",E25*H25) -> 0 | J25: Digi-Key | K25: Link | L25: Order with the PCB. | M25: Optional and not counted, my call. The Nucleo stays on the carrier board, so the bare chip is only needed if I later go chip-down. The price was found on a Digi-Key search result. | P25: Optional for now: the PCB is a carrier board that the Nucleo plugs into, so the chip stays on the Nucleo. Only needed if you later go chip-down (your own chip on your own board). STM32G474RET6 (64-pin LQFP) was $10.70 on a Digi-Key search result; check stock if you do. | Q25: Only if going chip-down | R25: Only if going chip-down (buy 2)
A26: 19 | B26: PCB | C26: 5 V module for the Pi - OPTION A (counted) | D26: Pololu D24V50F5, 5 V 5 A step-down regulator (item 2851) | E26: 1 | F26: PCB | G26: Verified | H26: 32.95 | I26: =IF(H26="","",E26*H26) -> 32.95 | J26: Pololu | K26: Link | L26: 220 in stock (Oct 17). Order with the PCB. | M26: The Pi needs a steady 5 V at about 5 A. I asked which design was more time-efficient and looked cleaner and more professional, and chose to have the PCB power the Pi, because I need the PCB by Prototype 2/3 anyway. A ready-made module that plugs into a socket means no regulator design. Option A is the known-good one from Pololu. I said to hold the choice for about a week (around Oct 24). | P26: Known-good option. Needed for the final PCB (Prototype 3). In Prototype 2 the Pi runs on its wall supply instead. Option B below is cheaper but unproven. | Q26: ~Oct 24 (a week out); before PCB layout | R26: With the PCB, Nov 1-3
A27: 20 | B27: PCB | C27: 5 V module for the Pi - OPTION B (not counted) | D27: Generic 24V/12V to 5V 5A buck module, AliExpress (listing 3256809254781510) | E27: 0 | F27: PCB | G27: Needs check | H27: 5.24 | I27: =IF(H27="","",E27*H27) -> 0 | J27: AliExpress | K27: Link | L27: Ships from China, likely 1-3 weeks (not checked). | M27: A much cheaper alternative I found, kept as a second option. The seller's 5 A claim needs testing with a meter before it ever powers a Pi. I will decide between A and B in about a week. | P27: The two options for the 5 V part are A (Pololu) and B (this). $5.24 normal price, 4.8 stars from only 58 reviews. The '5 A' claim is doubtful on this type of board; test with a meter and a dummy load before connecting a Pi. Footprint differs from Option A, so pick before the PCB layout is final. | Q27: ~Oct 24 (a week out) | R27: If chosen: by Oct 24 (China, 1-3 weeks)
A28: 21 | B28: PCB | C28: Connectors, passives, headers | D28: Screw terminals, female headers for the Nucleo to plug into, resistors, capacitors for the PCB | E28: 1 | F28: PCB | G28: Estimate | H28: 15 | I28: =IF(H28="","",E28*H28) -> 15 | J28: ECE shop / Digi-Key | L28: Order with the PCB. | M28: The small parts that finish the board. General items like these may be free from the Purdue ECE shop, so much of this may cost nothing. | P28: Much of this may be free from the ECE shop. | Q28: Oct 30 | R28: Nov 1-3
C29: PCB TOTAL | I29: =SUMIFS($I$5:$I$28,$F$5:$F$28,"PCB") -> 72.95
A30: PROTOTYPE 2 - order about Nov 17 (Pi wired to motors, live tracking)
A31: 22 | B31: Vision | C31: Raspberry Pi 5 (8 GB) | D31: Raspberry Pi 5 8GB, board only (CanaKit SKU PI5-8GB) | E31: 1 | F31: P2 | G31: Verified | H31: 175 | I31: =IF(H31="","",E31*H31) -> 175 | J31: CanaKit | K31: Link | L31: In stock per the page; shipping time not checked. | M31: I chose the 8 GB version and said I did not want the 4 GB: the RAM cannot be upgraded later, and the extra room helps with bigger models and the semester 2 drone work. I decided NOT to buy the Pi now; it is a Prototype 2 purchase, ordered by about Nov 13. Training happens on my laptop or Colab, and the Pi only runs the finished model. | P31: PiShop also lists $175. Adafruit lists $200. The 4 GB is $110 at CanaKit (not chosen). | Q31: Pi + camera timing: see open question | R31: By Nov 13 (arrive before Nov 20) unless pulled forward
A32: 23 | B32: Vision | C32: Pi power supply | D32: RasTech 27 W GaN USB-C PD supply, 5.1 V 5 A for Raspberry Pi 5 (ASIN B0CLV6WB4L) | E32: 1 | F32: P2 | G32: Needs check | H32: 12.34 | I32: =IF(H32="","",E32*H32) -> 12.34 | J32: Amazon | K32: Link | L32: Not seen. Check the listing. | M32: In Prototype 2 the Pi runs from its own wall supply so a bug in the brand-new PCB cannot ruin the checkpoint. The Pi wants 5 V at 5 A; a weaker charger can make it crash. | P32: Official Pi 27 W supply is $22.91 on Amazon if you want the safest option. Check reviews for 5 A output. | Q32: Nov 10 | R32: By Nov 13
A33: 24 | B33: Vision | C33: Pi cooler | D33: Raspberry Pi 5 Active Cooler (CanaKit SKU RSP-ACTIVE-COOLER) | E33: 1 | F33: P2 | G33: Verified | H33: 11.95 | I33: =IF(H33="","",E33*H33) -> 11.95 | J33: CanaKit | K33: Link | L33: In stock per the page. | M33: Running the model makes the Pi hot and a hot Pi slows itself down. A heatsink with a small fan keeps it fast during a demo. A passive heatsink from the ECE shop may do. | P33: Order with the Pi to save shipping. A passive heatsink from the ECE shop may work if it is cooler where you test. | Q33: Nov 10 | R33: By Nov 13
A34: 25 | B34: Vision | C34: Coral USB Accelerator (optional) | D34: Google Coral USB Accelerator, Edge TPU, model G950-01456-01 (Amazon listing B07S214S5Y) | E34: 0 | F34: P2 | G34: Needs check | H34: 135 | I34: =IF(H34="","",E34*H34) -> 0 | J34: Amazon | K34: Link | L34: Amazon search result showed delivery Fri Oct 23 (confirm at checkout). | M34: I asked what I lose without it and why I need another chip to run the model. Answer: the Pi 5's own chip probably runs the model fast enough, and a benchmark says the Pi 5 is about on par for this kind of model. I chose to PIN it as optional because it plugs into the Pi over USB, so adding it later changes nothing on the PCB or the wiring. The price swings from $89 to $200 and the Newark listing will not deliver until 2027. I decide at P2 after measuring the Pi alone. | P34: Qty 0 so it is not counted. Prices for the same product vary by seller ($108.99 to $199.99 on Amazon; this $135.00 listing is the one you picked). Newark lists it at $89.35 (https://www.newark.com/coral/g950-01456-01/usb-accelerator-raspberry-pi/dp/26AJ4884) but says deliveries start 1/10/2027 and the lead time is 41 weeks, so it will not arrive before Dec 12. Evidence that you may not need it: Hackster's benchmark says Pi 5 TFLite performance is roughly on par with the Coral for MobileNet SSD models, and a Pi 4 CPU manages 2-5 fps. | Q34: Nov 24 (after measuring the Pi alone) | R34: Only if needed
A35: 26 | B35: Vision | C35: microSD card | D35: 32 GB or larger microSD card | E35: 1 | F35: P2 | G35: Open | I35: =IF(H35="","",E35*H35) | J35: ECE shop or own | M35: The Pi boots from this and stores the model. Probably free from the ECE shop or a card I already own. | P35: Probably free from the ECE shop or a card you already own. | Q35: Nov 10 | R35: By Nov 13 (or ECE shop)
C36: PROTOTYPE 2 TOTAL | I36: =SUMIFS($I$5:$I$35,$F$5:$F$35,"P2") -> 199.29
A37: OPTIONAL / NOT COUNTED (qty 0): battery set and alternatives. Decide in late November.
A38: 27 | B38: Power | C38: Battery charger | D38: Waveshare PSU-12.6V2A-5.5-2.1-US (12.6 V, 2 A) | E38: 0 | F38: P3 | G38: Needs check | H38: 6.99 | I38: =IF(H38="","",E38*H38) -> 0 | J38: Waveshare | K38: Link | L38: Not verified. | M38: I decided no battery pack yet. The battery set is optional and not counted; I can add it later once I am committed to the project. Needed only if I build the pack. | P38: Only needed if you build the battery pack. | Q38: Late November | R38: Only if building a battery
A39: 28 | B39: Power | C39: Power switch + reverse-polarity protection | D39: Pololu Big Pushbutton Power Switch with Reverse Voltage Protection, HP (item #2813) | E39: 0 | F39: P3 | G39: Verified | H39: 8.95 | I39: =IF(H39="","",E39*H39) -> 0 | J39: Pololu | K39: Link | L39: Pololu ships same day from Las Vegas; confirm at checkout. | M39: Part of the optional battery set I decided to hold off on. A push-button switch that also blocks a backwards battery. | P39: Not an emergency cutoff. Only needed with the battery. | Q39: Late November | R39: Only if building a battery
A40: 29 | B40: Power | C40: Battery pack | D40: 3S2P 18650 pack with BMS, >= 6 Ah, BMS >= 15 A. Build or buy decided at P3 | E40: 0 | F40: P3 | G40: Open | H40: 42 | I40: =IF(H40="","",E40*H40) -> 0 | J40: TBD | M40: I asked why the battery is so expensive and chose to leave it out for now and run from the wall adapter. Buy-or-build is a late-November decision; the price is an estimate for a DIY pack. | P40: Price is my estimate for a DIY pack ($40-45). Pre-made packs I found miss the current spec or lack a stated BMS. | Q40: Late November | R40: Only if building a battery
A41: 30 | B41: Motion | C41: ALTERNATIVE: Stepper motor (pan + tilt) | D41: STEPPERONLINE NEMA 17 bipolar stepper, 2 A, 59 Ncm, 48 mm body, 1 m cable (ASIN B00PNEQKC0) | E41: 0 | F41: ALT | G41: Verified | H41: 14.99 | I41: =IF(H41="","",E41*H41) -> 0 | J41: Amazon | K41: Link | L41: Amazon Prime. Listing showed free delivery Sun Oct 18 (confirm at checkout). | M41: Not counted. I went back to closed-loop kits; this open-loop option stays only as a fallback. | P41: Not counted: we went back to closed-loop kits. Plain (open-loop) stepper: no position sensor. Fine for a light load. Encoder feedback is a stretch goal. | Q41: n/a | R41: n/a
...

Sheet Summary
A1: Budget summary
A3: Budget target ($) | B3: 380 | C3: Your target. Change it here and everything below updates. Shipping and tax are NOT in these numbers.
A5: Prototype 1 (order now) | B5: =SUMIFS(BOM!$I$5:$I$47,BOM!$F$5:$F$47,"P1") -> 177.28 | C5: Closed-loop kits, dev board, laser, power parts.
A6: PCB (order by Nov 2) | B6: =SUMIFS(BOM!$I$5:$I$47,BOM!$F$5:$F$47,"PCB") -> 72.95 | C6: Estimates; depends on your design.
A7: Prototype 2 (order ~Nov 17) | B7: =SUMIFS(BOM!$I$5:$I$47,BOM!$F$5:$F$47,"P2") -> 199.29 | C7: Pi 5 8 GB, power supply, cooler, Camera Module 3, cable.
A8: Shipping + tax allowance (estimate) | B8: =SUMIFS(BOM!$I$5:$I$47,BOM!$F$5:$F$47,"SHIP") -> 80 | C8: Replace with real checkout totals.
A9: Prototype 3 / optional (battery) | B9: =SUMIFS(BOM!$I$5:$I$47,BOM!$F$5:$F$47,"P3") -> 0 | C9: Qty 0 right now, so not counted. Coral is also not counted (see Coral row).
A10: TOTAL (counted rows) | B10: =SUM(B5:B9) -> 529.52
A11: Remaining vs target | B11: =B3-B10 -> -149.52 | C11: Negative (red) means over target.
A13: If you add the battery set later (reference) | B13: =SUMIFS(BOM!$H$5:$H$47,BOM!$F$5:$F$47,"P3") -> 57.94 | C13: Charger + switch + pack estimate.
A14: Coral USB Accelerator (optional) | B14: =SUMIFS(BOM!$H$5:$H$47,BOM!$C$5:$C$47,"*Coral*") -> 135 | C14: Decide at P2 after measuring the Pi alone.
A16: GRAND TOTAL WITHOUT optional items | B16: =B10 -> 529.52 | C16: Everything you actually need, incl. shipping/tax allowance.
A17: GRAND TOTAL WITH optional items | B17: =B10+B13+B14 -> 722.46 | C17: Adds battery set + Coral.
A19: Counted rows still 'Estimate' or unpriced | B19: =COUNTIFS(BOM!$E$5:$E$47,">0",BOM!$G$5:$G$47,"Estimate")+COUNTIFS(BOM!$E$5:$E$47,">0",BOM!$H$5:$H$47,"") -> 8 | C19: Rows whose price is a guess or missing.
A20: Counted rows marked Verified | B20: =COUNTIFS(BOM!$E$5:$E$47,">0",BOM!$G$5:$G$47,"Verified") -> 8 | C20: Seen on the live listing.
A22: Things the Purdue ECE shop might cover (ask)
A23: - Nucleo dev board (saves $20)
A24: - 12 V adapter, barrel jack, fuse holder, 1000 uF capacitor, MOSFET (saves ~$30-40)
A25: - microSD card, spare wire and connectors

Sheet Legend
A1: Status
A2: Verified | B2: I opened the live product page and saw this price and stock.
A3: Needs check | B3: Price came from a search result or a detail is unconfirmed. Check it before buying.
A4: Estimate | B4: My guess. No listing yet.
A5: Owned / Borrowed | B5: Not purchased, not counted.
A6: Qty 0 | B6: Not counted in totals (owned, optional, or an alternative).
A7: Yellow cells | B7: CAD and KiCad footprints, filled in later.
A8: Safety | B8: Laser must be 1 mW or less (Class 2). Never aim it at people or mirrors. The Amazon $15.99 'Class 3R' module is NOT used.
